<?xml version="1.0" encoding="utf-8"?>
<!-- This URDF was automatically created by SolidWorks to URDF Exporter! Originally created by Stephen Brawner (brawner@gmail.com) 
     Commit Version: 1.6.0-4-g7f85cfe  Build Version: 1.6.7995.38578
     For more information, please see http://wiki.ros.org/sw_urdf_exporter -->
<robot
  name="FullAssemblyPyBullet">
  <link
    name="MainBody">
    <inertial>
      <origin
        xyz="0.072878582499047 -0.00026929353661051 0.0386375641254821"
        rpy="0 0 0" />
      <mass
        value="1.62403957260971" />
      <inertia
        ixx="0.00425087317864028"
        ixy="-3.43872307352827E-07"
        ixz="2.81226041199486E-06"
        iyy="0.00391606111758808"
        iyz="1.19851821234013E-08"
        izz="0.00728669871541611" />
    </inertial>
    <visual>
      <origin
        xyz="0 0 0"
        rpy="0 0 0" />
      <geometry>
        <mesh
          filename="package://FullAssemblyPyBullet/meshes/MainBody.STL" />
      </geometry>
      <material
        name="">
        <color
          rgba="0.752941176470588 0.752941176470588 0.752941176470588 1" />
      </material>
    </visual>
    <collision>
      <origin
        xyz="0 0 0"
        rpy="0 0 0" />
      <geometry>
        <mesh
          filename="package://FullAssemblyPyBullet/meshes/MainBody.STL" />
      </geometry>
    </collision>
  </link>
  <link
    name="FL_Main">
    <inertial>
      <origin
        xyz="-0.0142129389773466 1.62894733391206E-05 0.000867107009490387"
        rpy="0 0 0" />
      <mass
        value="0.0545853538861373" />
      <inertia
        ixx="2.08305063667721E-05"
        ixy="-1.16614215775999E-08"
        ixz="3.92075468314115E-23"
        iyy="1.37106620174681E-05"
        iyz="-2.2727203883899E-21"
        izz="1.36884897771704E-05" />
    </inertial>
    <visual>
      <origin
        xyz="0 0 0"
        rpy="0 0 0" />
      <geometry>
        <mesh
          filename="package://FullAssemblyPyBullet/meshes/FL_Main.STL" />
      </geometry>
      <material
        name="">
        <color
          rgba="0.752941176470588 0.752941176470588 0.752941176470588 1" />
      </material>
    </visual>
    <collision>
      <origin
        xyz="0 0 0"
        rpy="0 0 0" />
      <geometry>
        <mesh
          filename="package://FullAssemblyPyBullet/meshes/FL_Main.STL" />
      </geometry>
    </collision>
  </link>
  <joint
    name="FL_Main"
    type="fixed">
    <origin
      xyz="0.3098 0.1 0.037"
      rpy="0 0 0" />
    <parent
      link="MainBody" />
    <child
      link="FL_Main" />
    <axis
      xyz="0 0 0" />
  </joint>
  <link
    name="FL_Hip">
    <inertial>
      <origin
        xyz="-0.046482 -0.013937 -0.00013148"
        rpy="0 0 0" />
      <mass
        value="0.092628" />
      <inertia
        ixx="2.6348E-05"
        ixy="1.0623E-06"
        ixz="2.1924E-09"
        iyy="4.2592E-05"
        iyz="-1.0475E-07"
        izz="2.9112E-05" />
    </inertial>
    <visual>
      <origin
        xyz="0 0 0"
        rpy="0 0 0" />
      <geometry>
        <mesh
          filename="package://FullAssemblyPyBullet/meshes/FL_Hip.STL" />
      </geometry>
      <material
        name="">
        <color
          rgba="0.75294 0.75294 0.75294 1" />
      </material>
    </visual>
    <collision>
      <origin
        xyz="0 0 0"
        rpy="0 0 0" />
      <geometry>
        <mesh
          filename="package://FullAssemblyPyBullet/meshes/FL_Hip.STL" />
      </geometry>
    </collision>
  </link>
  <joint
    name="FL_Hip"
    type="revolute">
    <origin
      xyz="-0.022 0 0.00086711"
      rpy="0 0 0" />
    <parent
      link="FL_Main" />
    <child
      link="FL_Hip" />
    <axis
      xyz="1 0 0" />
    <limit
      lower="-0.175"
      upper="1.57"
      effort="0"
      velocity="0" />
  </joint>
  <link
    name="FL_Femur">
    <inertial>
      <origin
        xyz="-0.0192209156804704 0.0445309182127519 -0.0180483752178875"
        rpy="0 0 0" />
      <mass
        value="0.162698622822929" />
      <inertia
        ixx="0.000127956505961255"
        ixy="-2.78799082360857E-06"
        ixz="-8.05949151113297E-05"
        iyy="0.000233954696541122"
        iyz="-2.77405486023309E-06"
        izz="0.000124359017081198" />
    </inertial>
    <visual>
      <origin
        xyz="0 0 0"
        rpy="0 0 0" />
      <geometry>
        <mesh
          filename="package://FullAssemblyPyBullet/meshes/FL_Femur.STL" />
      </geometry>
      <material
        name="">
        <color
          rgba="0.752941176470588 0.752941176470588 0.752941176470588 1" />
      </material>
    </visual>
    <collision>
      <origin
        xyz="0 0 0"
        rpy="0 0 0" />
      <geometry>
        <mesh
          filename="package://FullAssemblyPyBullet/meshes/FL_Femur.STL" />
      </geometry>
    </collision>
  </link>
  <joint
    name="FL_Femur"
    type="revolute">
    <origin
      xyz="-0.054 -0.009 0"
      rpy="0 0 0" />
    <parent
      link="FL_Hip" />
    <child
      link="FL_Femur" />
    <axis
      xyz="0 1 0" />
    <limit
      lower="-0.785"
      upper="0.785"
      effort="0"
      velocity="0" />
  </joint>
  <link
    name="FL_Tibia">
    <inertial>
      <origin
        xyz="0.0322222803661381 2.3950333778347E-05 -0.0963070790588942"
        rpy="0 0 0" />
      <mass
        value="0.109742713288899" />
      <inertia
        ixx="0.000412146616277659"
        ixy="-9.37703218432666E-07"
        ixz="0.000137719050427429"
        iyy="0.000472843862495806"
        iyz="2.22230783760562E-06"
        izz="6.65211240358334E-05" />
    </inertial>
    <visual>
      <origin
        xyz="0 0 0"
        rpy="0 0 0" />
      <geometry>
        <mesh
          filename="package://FullAssemblyPyBullet/meshes/FL_Tibia.STL" />
      </geometry>
      <material
        name="">
        <color
          rgba="0.752941176470588 0.752941176470588 0.752941176470588 1" />
      </material>
    </visual>
    <collision>
      <origin
        xyz="0 0 0"
        rpy="0 0 0" />
      <geometry>
        <mesh
          filename="package://FullAssemblyPyBullet/meshes/FL_Tibia.STL" />
      </geometry>
    </collision>
  </link>
  <joint
    name="FL_Tibia"
    type="revolute">
    <origin
      xyz="-0.1283 0.0695 -0.1404"
      rpy="0 0 0" />
    <parent
      link="FL_Femur" />
    <child
      link="FL_Tibia" />
    <axis
      xyz="0 1 0" />
    <limit
      lower="-1.57"
      upper="0"
      effort="0"
      velocity="0" />
  </joint>
  <link
    name="FR_Main">
    <inertial>
      <origin
        xyz="-0.0142129389773466 -1.62894733438113E-05 0.000867107009486667"
        rpy="0 0 0" />
      <mass
        value="0.0545853538861373" />
      <inertia
        ixx="2.08305063667721E-05"
        ixy="1.16614215775987E-08"
        ixz="6.97074471618248E-22"
        iyy="1.37106620174681E-05"
        iyz="-3.82852114822138E-21"
        izz="1.36884897771704E-05" />
    </inertial>
    <visual>
      <origin
        xyz="0 0 0"
        rpy="0 0 0" />
      <geometry>
        <mesh
          filename="package://FullAssemblyPyBullet/meshes/FR_Main.STL" />
      </geometry>
      <material
        name="">
        <color
          rgba="0.752941176470588 0.752941176470588 0.752941176470588 1" />
      </material>
    </visual>
    <collision>
      <origin
        xyz="0 0 0"
        rpy="0 0 0" />
      <geometry>
        <mesh
          filename="package://FullAssemblyPyBullet/meshes/FR_Main.STL" />
      </geometry>
    </collision>
  </link>
  <joint
    name="FR_Main"
    type="fixed">
    <origin
      xyz="0.3098 -0.1 0.037"
      rpy="0 0 0" />
    <parent
      link="MainBody" />
    <child
      link="FR_Main" />
    <axis
      xyz="0 0 0" />
  </joint>
  <link
    name="FR_Hip">
    <inertial>
      <origin
        xyz="-0.0464814846151319 0.0139368074596899 -0.00013139899879927"
        rpy="0 0 0" />
      <mass
        value="0.0926281571943994" />
      <inertia
        ixx="2.63478370427054E-05"
        ixy="-1.06235962314716E-06"
        ixz="2.09491675922292E-09"
        iyy="4.25917798152951E-05"
        iyz="1.04671109592226E-07"
        izz="2.91124797402975E-05" />
    </inertial>
    <visual>
      <origin
        xyz="0 0 0"
        rpy="0 0 0" />
      <geometry>
        <mesh
          filename="package://FullAssemblyPyBullet/meshes/FR_Hip.STL" />
      </geometry>
      <material
        name="">
        <color
          rgba="0.752941176470588 0.752941176470588 0.752941176470588 1" />
      </material>
    </visual>
    <collision>
      <origin
        xyz="0 0 0"
        rpy="0 0 0" />
      <geometry>
        <mesh
          filename="package://FullAssemblyPyBullet/meshes/FR_Hip.STL" />
      </geometry>
    </collision>
  </link>
  <joint
    name="FR_Hip"
    type="revolute">
    <origin
      xyz="-0.022 0 0.00086711"
      rpy="0 0 0" />
    <parent
      link="FR_Main" />
    <child
      link="FR_Hip" />
    <axis
      xyz="1 0 0" />
    <limit
      lower="-1.57"
      upper="0.175"
      effort="0"
      velocity="0" />
  </joint>
  <link
    name="FR_Femur">
    <inertial>
      <origin
        xyz="-0.0192209201999718 -0.0445309199407908 -0.018048379316567"
        rpy="0 0 0" />
      <mass
        value="0.162698598408838" />
      <inertia
        ixx="0.000127956696460808"
        ixy="2.78797473958634E-06"
        ixz="-8.05951042892452E-05"
        iyy="0.000233955012448174"
        iyz="2.77402832705289E-06"
        izz="0.000124359143094938" />
    </inertial>
    <visual>
      <origin
        xyz="0 0 0"
        rpy="0 0 0" />
      <geometry>
        <mesh
          filename="package://FullAssemblyPyBullet/meshes/FR_Femur.STL" />
      </geometry>
      <material
        name="">
        <color
          rgba="0.752941176470588 0.752941176470588 0.752941176470588 1" />
      </material>
    </visual>
    <collision>
      <origin
        xyz="0 0 0"
        rpy="0 0 0" />
      <geometry>
        <mesh
          filename="package://FullAssemblyPyBullet/meshes/FR_Femur.STL" />
      </geometry>
    </collision>
  </link>
  <joint
    name="FR_Femur"
    type="revolute">
    <origin
      xyz="-0.054 0.009 0"
      rpy="0 0 0" />
    <parent
      link="FR_Hip" />
    <child
      link="FR_Femur" />
    <axis
      xyz="0 1 0" />
    <limit
      lower="-0.785"
      upper="0.785"
      effort="0"
      velocity="0" />
  </joint>
  <link
    name="FR_Tibia">
    <inertial>
      <origin
        xyz="0.0322222611125705 -2.39005330520126E-05 -0.0963069941315003"
        rpy="0 0 0" />
      <mass
        value="0.109742907140872" />
      <inertia
        ixx="0.000412147652732025"
        ixy="9.37732808955413E-07"
        ixz="0.000137719346796874"
        iyy="0.000472844994490274"
        iyz="-2.22242070608849E-06"
        izz="6.65212356877185E-05" />
    </inertial>
    <visual>
      <origin
        xyz="0 0 0"
        rpy="0 0 0" />
      <geometry>
        <mesh
          filename="package://FullAssemblyPyBullet/meshes/FR_Tibia.STL" />
      </geometry>
      <material
        name="">
        <color
          rgba="0.752941176470588 0.752941176470588 0.752941176470588 1" />
      </material>
    </visual>
    <collision>
      <origin
        xyz="0 0 0"
        rpy="0 0 0" />
      <geometry>
        <mesh
          filename="package://FullAssemblyPyBullet/meshes/FR_Tibia.STL" />
      </geometry>
    </collision>
  </link>
  <joint
    name="FR_Tibia"
    type="revolute">
    <origin
      xyz="-0.1283 -0.0695 -0.1404"
      rpy="0 0 0" />
    <parent
      link="FR_Femur" />
    <child
      link="FR_Tibia" />
    <axis
      xyz="0 1 0" />
    <limit
      lower="-1.57"
      upper="0"
      effort="0"
      velocity="0" />
  </joint>
  <link
    name="RL_Main">
    <inertial>
      <origin
        xyz="-0.0142129389773467 -1.62894733400781E-05 -5.55111512312578E-17"
        rpy="0 0 0" />
      <mass
        value="0.0545853538861374" />
      <inertia
        ixx="2.08305063667722E-05"
        ixy="1.16614215776012E-08"
        ixz="-4.31615841781513E-22"
        iyy="1.37106620174681E-05"
        iyz="-1.43391290760765E-21"
        izz="1.36884897771704E-05" />
    </inertial>
    <visual>
      <origin
        xyz="0 0 0"
        rpy="0 0 0" />
      <geometry>
        <mesh
          filename="package://FullAssemblyPyBullet/meshes/RL_Main.STL" />
      </geometry>
      <material
        name="">
        <color
          rgba="0.752941176470588 0.752941176470588 0.752941176470588 1" />
      </material>
    </visual>
    <collision>
      <origin
        xyz="0 0 0"
        rpy="0 0 0" />
      <geometry>
        <mesh
          filename="package://FullAssemblyPyBullet/meshes/RL_Main.STL" />
      </geometry>
    </collision>
  </link>
  <joint
    name="RL_Main"
    type="fixed">
    <origin
      xyz="-0.1574 0.1 0.037"
      rpy="0 0 0" />
    <parent
      link="MainBody" />
    <child
      link="RL_Main" />
    <axis
      xyz="0 0 0" />
  </joint>
  <link
    name="RL_Hip">
    <inertial>
      <origin
        xyz="-0.0464815930364211 -0.0139367878529174 -0.00013153961663237"
        rpy="0 0 0" />
      <mass
        value="0.0926279267964104" />
      <inertia
        ixx="2.63477414071249E-05"
        ixy="1.06227692183182E-06"
        ixz="2.19055687599929E-09"
        iyy="4.25916540154744E-05"
        iyz="-1.04787330349468E-07"
        izz="2.91123437962376E-05" />
    </inertial>
    <visual>
      <origin
        xyz="0 0 0"
        rpy="0 0 0" />
      <geometry>
        <mesh
          filename="package://FullAssemblyPyBullet/meshes/RL_Hip.STL" />
      </geometry>
      <material
        name="">
        <color
          rgba="0.752941176470588 0.752941176470588 0.752941176470588 1" />
      </material>
    </visual>
    <collision>
      <origin
        xyz="0 0 0"
        rpy="0 0 0" />
      <geometry>
        <mesh
          filename="package://FullAssemblyPyBullet/meshes/RL_Hip.STL" />
      </geometry>
    </collision>
  </link>
  <joint
    name="RL_Hip"
    type="revolute">
    <origin
      xyz="-0.022 0 0"
      rpy="0 0 0" />
    <parent
      link="RL_Main" />
    <child
      link="RL_Hip" />
    <axis
      xyz="1 0 0" />
    <limit
      lower="-0.175"
      upper="1.57"
      effort="0"
      velocity="0" />
  </joint>
  <link
    name="RL_Femur">
    <inertial>
      <origin
        xyz="-0.0192209157084933 0.0445309180696282 -0.0180483751384093"
        rpy="0 0 0" />
      <mass
        value="0.162698622211317" />
      <inertia
        ixx="0.000127956505837028"
        ixy="-2.78799083584668E-06"
        ixz="-8.05949147183145E-05"
        iyy="0.000233954695159338"
        iyz="-2.7740548625348E-06"
        izz="0.000124359015823795" />
    </inertial>
    <visual>
      <origin
        xyz="0 0 0"
        rpy="0 0 0" />
      <geometry>
        <mesh
          filename="package://FullAssemblyPyBullet/meshes/RL_Femur.STL" />
      </geometry>
      <material
        name="">
        <color
          rgba="0.752941176470588 0.752941176470588 0.752941176470588 1" />
      </material>
    </visual>
    <collision>
      <origin
        xyz="0 0 0"
        rpy="0 0 0" />
      <geometry>
        <mesh
          filename="package://FullAssemblyPyBullet/meshes/RL_Femur.STL" />
      </geometry>
    </collision>
  </link>
  <joint
    name="RL_Femur"
    type="revolute">
    <origin
      xyz="-0.054 -0.009 0"
      rpy="0 0 0" />
    <parent
      link="RL_Hip" />
    <child
      link="RL_Femur" />
    <axis
      xyz="0 1 0" />
    <limit
      lower="-0.785"
      upper="0.785"
      effort="0"
      velocity="0" />
  </joint>
  <link
    name="RL_Tibia">
    <inertial>
      <origin
        xyz="0.032222 2.395E-05 -0.096307"
        rpy="0 0 0" />
      <mass
        value="0.10974" />
      <inertia
        ixx="0.00041215"
        ixy="-9.377E-07"
        ixz="0.00013772"
        iyy="0.00047284"
        iyz="2.2223E-06"
        izz="6.6521E-05" />
    </inertial>
    <visual>
      <origin
        xyz="0 0 0"
        rpy="0 0 0" />
      <geometry>
        <mesh
          filename="package://FullAssemblyPyBullet/meshes/RL_Tibia.STL" />
      </geometry>
      <material
        name="">
        <color
          rgba="0.75294 0.75294 0.75294 1" />
      </material>
    </visual>
    <collision>
      <origin
        xyz="0 0 0"
        rpy="0 0 0" />
      <geometry>
        <mesh
          filename="package://FullAssemblyPyBullet/meshes/RL_Tibia.STL" />
      </geometry>
    </collision>
  </link>
  <joint
    name="RL_Tibia"
    type="revolute">
    <origin
      xyz="-0.1283 0.0695 -0.1404"
      rpy="0 0 0" />
    <parent
      link="RL_Femur" />
    <child
      link="RL_Tibia" />
    <axis
      xyz="0 1 0" />
    <limit
      lower="-1.57"
      upper="0"
      effort="0"
      velocity="0" />
  </joint>
  <link
    name="RR_Main">
    <inertial>
      <origin
        xyz="0 0 0"
        rpy="0 0 0" />
      <mass
        value="0" />
      <inertia
        ixx="0"
        ixy="0"
        ixz="0"
        iyy="0"
        iyz="0"
        izz="0" />
    </inertial>
    <visual>
      <origin
        xyz="0 0 0"
        rpy="0 0 0" />
      <geometry>
        <mesh
          filename="package://FullAssemblyPyBullet/meshes/RR_Main.STL" />
      </geometry>
      <material
        name="">
        <color
          rgba="1 1 1 1" />
      </material>
    </visual>
    <collision>
      <origin
        xyz="0 0 0"
        rpy="0 0 0" />
      <geometry>
        <mesh
          filename="package://FullAssemblyPyBullet/meshes/RR_Main.STL" />
      </geometry>
    </collision>
  </link>
  <joint
    name="RR_Main"
    type="fixed">
    <origin
      xyz="-0.1574 -0.099999999999999 0.0370000000000011"
      rpy="0 0 0" />
    <parent
      link="MainBody" />
    <child
      link="RR_Main" />
    <axis
      xyz="0 0 0" />
  </joint>
  <link
    name="RR_Hip">
    <inertial>
      <origin
        xyz="-0.0464814378828995 0.013936787220023 -0.000131456647172179"
        rpy="0 0 0" />
      <mass
        value="0.0926285030937888" />
      <inertia
        ixx="2.63479448635204E-05"
        ixy="-1.06236260344054E-06"
        ixz="2.09302194462647E-09"
        iyy="4.25918877263147E-05"
        iyz="1.04706303472326E-07"
        izz="2.91125133706958E-05" />
    </inertial>
    <visual>
      <origin
        xyz="0 0 0"
        rpy="0 0 0" />
      <geometry>
        <mesh
          filename="package://FullAssemblyPyBullet/meshes/RR_Hip.STL" />
      </geometry>
      <material
        name="">
        <color
          rgba="0.752941176470588 0.752941176470588 0.752941176470588 1" />
      </material>
    </visual>
    <collision>
      <origin
        xyz="0 0 0"
        rpy="0 0 0" />
      <geometry>
        <mesh
          filename="package://FullAssemblyPyBullet/meshes/RR_Hip.STL" />
      </geometry>
    </collision>
  </link>
  <joint
    name="RR_Hip"
    type="revolute">
    <origin
      xyz="-0.022 0 0"
      rpy="0 0 0" />
    <parent
      link="RR_Main" />
    <child
      link="RR_Hip" />
    <axis
      xyz="1 0 0" />
    <limit
      lower="-1.57"
      upper="0.175"
      effort="0"
      velocity="0" />
  </joint>
  <link
    name="RR_Femur">
    <inertial>
      <origin
        xyz="-0.0192209202181283 -0.0445309198933593 -0.0180483792970791"
        rpy="0 0 0" />
      <mass
        value="0.16269859820821" />
      <inertia
        ixx="0.000127956696378507"
        ixy="2.78797474241707E-06"
        ixz="-8.05951040727679E-05"
        iyy="0.000233955011789758"
        iyz="2.77402832806782E-06"
        izz="0.000124359142518754" />
    </inertial>
    <visual>
      <origin
        xyz="0 0 0"
        rpy="0 0 0" />
      <geometry>
        <mesh
          filename="package://FullAssemblyPyBullet/meshes/RR_Femur.STL" />
      </geometry>
      <material
        name="">
        <color
          rgba="0.752941176470588 0.752941176470588 0.752941176470588 1" />
      </material>
    </visual>
    <collision>
      <origin
        xyz="0 0 0"
        rpy="0 0 0" />
      <geometry>
        <mesh
          filename="package://FullAssemblyPyBullet/meshes/RR_Femur.STL" />
      </geometry>
    </collision>
  </link>
  <joint
    name="RR_Femur"
    type="revolute">
    <origin
      xyz="-0.054 0.009 0"
      rpy="0 0 0" />
    <parent
      link="RR_Hip" />
    <child
      link="RR_Femur" />
    <axis
      xyz="0 1 0" />
    <limit
      lower="-0.785"
      upper="0.785"
      effort="0"
      velocity="0" />
  </joint>
  <link
    name="RR_Tibia">
    <inertial>
      <origin
        xyz="0.032222261112571 -2.39005330522346E-05 -0.0963069941314975"
        rpy="0 0 0" />
      <mass
        value="0.109742907140872" />
      <inertia
        ixx="0.000412147652732022"
        ixy="9.37732808955304E-07"
        ixz="0.000137719346796875"
        iyy="0.000472844994490267"
        iyz="-2.22242070608834E-06"
        izz="6.65212356877155E-05" />
    </inertial>
    <visual>
      <origin
        xyz="0 0 0"
        rpy="0 0 0" />
      <geometry>
        <mesh
          filename="package://FullAssemblyPyBullet/meshes/RR_Tibia.STL" />
      </geometry>
      <material
        name="">
        <color
          rgba="0.752941176470588 0.752941176470588 0.752941176470588 1" />
      </material>
    </visual>
    <collision>
      <origin
        xyz="0 0 0"
        rpy="0 0 0" />
      <geometry>
        <mesh
          filename="package://FullAssemblyPyBullet/meshes/RR_Tibia.STL" />
      </geometry>
    </collision>
  </link>
  <joint
    name="RR_Tibia"
    type="revolute">
    <origin
      xyz="-0.1283 -0.0695 -0.1404"
      rpy="0 0 0" />
    <parent
      link="RR_Femur" />
    <child
      link="RR_Tibia" />
    <axis
      xyz="0 1 0" />
    <limit
      lower="-1.57"
      upper="0"
      effort="0"
      velocity="0" />
  </joint>
</robot>